<?xml version="1.0" encoding="UTF-8"?>
<testng-results ignored="1" total="4" passed="1" failed="1" skipped="1">
  <reporter-output>
  </reporter-output>
  <suite started-at="2022-09-27T16:10:42 IST" name="Default suite" finished-at="2022-09-27T16:10:43 IST" duration-ms="1159">
    <groups>
    </groups>
    <test started-at="2022-09-27T16:10:42 IST" name="Default test" finished-at="2022-09-27T16:10:43 IST" duration-ms="1159">
      <class name="basic.Annotations2">
        <test-method signature="test1()[pri:-2, instance:basic.Annotations2@29647f75]" started-at="2022-09-27T16:10:42 IST" name="test1" finished-at="2022-09-27T16:10:42 IST" duration-ms="20" status="PASS">
          <reporter-output>
          </reporter-output>
        </test-method> <!-- test1 -->
        <test-method signature="test3()[pri:-1, instance:basic.Annotations2@29647f75]" started-at="2022-09-27T16:10:42 IST" name="test3" finished-at="2022-09-27T16:10:43 IST" duration-ms="1025" status="FAIL">
          <exception class="org.testng.internal.thread.ThreadTimeoutException">
            <message>
              <![CDATA[Method basic.Annotations2.test3() didn't finish within the time-out 1000]]>
            </message>
            <full-stacktrace>
              <![CDATA[org.testng.internal.thread.ThreadTimeoutException: Method basic.Annotations2.test3() didn't finish within the time-out 1000
at org.testng.internal.MethodInvocationHelper.invokeWithTimeoutWithNewExecutor(MethodInvocationHelper.java:384)
at org.testng.internal.MethodInvocationHelper.invokeWithTimeout(MethodInvocationHelper.java:283)
at org.testng.internal.TestInvoker.invokeMethod(TestInvoker.java:604)
at org.testng.internal.TestInvoker.invokeTestMethod(TestInvoker.java:173)
at org.testng.internal.MethodRunner.runInSequence(MethodRunner.java:46)
at org.testng.internal.TestInvoker$MethodInvocationAgent.invoke(TestInvoker.java:824)
at org.testng.internal.TestInvoker.invokeTestMethods(TestInvoker.java:146)
at org.testng.internal.TestMethodWorker.invokeTestMethods(TestMethodWorker.java:146)
at org.testng.internal.TestMethodWorker.run(TestMethodWorker.java:128)
at java.base/java.util.ArrayList.forEach(ArrayList.java:1511)
at org.testng.TestRunner.privateRun(TestRunner.java:794)
at org.testng.TestRunner.run(TestRunner.java:596)
at org.testng.SuiteRunner.runTest(SuiteRunner.java:377)
at org.testng.SuiteRunner.runSequentially(SuiteRunner.java:371)
at org.testng.SuiteRunner.privateRun(SuiteRunner.java:332)
at org.testng.SuiteRunner.run(SuiteRunner.java:276)
at org.testng.SuiteRunnerWorker.runSuite(SuiteRunnerWorker.java:53)
at org.testng.SuiteRunnerWorker.run(SuiteRunnerWorker.java:96)
at org.testng.TestNG.runSuitesSequentially(TestNG.java:1212)
at org.testng.TestNG.runSuitesLocally(TestNG.java:1134)
at org.testng.TestNG.runSuites(TestNG.java:1063)
at org.testng.TestNG.run(TestNG.java:1031)
at org.testng.remote.AbstractRemoteTestNG.run(AbstractRemoteTestNG.java:115)
at org.testng.remote.RemoteTestNG.initAndRun(RemoteTestNG.java:251)
at org.testng.remote.RemoteTestNG.main(RemoteTestNG.java:77)
]]>
            </full-stacktrace>
          </exception> <!-- org.testng.internal.thread.ThreadTimeoutException -->
          <reporter-output>
          </reporter-output>
        </test-method> <!-- test3 -->
        <test-method signature="test4()[pri:0, instance:basic.Annotations2@29647f75]" started-at="2022-09-27T16:10:43 IST" name="test4" finished-at="2022-09-27T16:10:43 IST" depends-on-methods="basic.Annotations2.test3" duration-ms="0" status="SKIP">
          <exception class="java.lang.Throwable">
            <message>
              <![CDATA[Method Annotations2.test4()[pri:0, instance:basic.Annotations2@29647f75] depends on not successfully finished methods]]>
            </message>
            <full-stacktrace>
              <![CDATA[java.lang.Throwable: Method Annotations2.test4()[pri:0, instance:basic.Annotations2@29647f75] depends on not successfully finished methods
at org.testng.internal.TestInvoker.invokeTestMethods(TestInvoker.java:102)
at org.testng.internal.TestMethodWorker.invokeTestMethods(TestMethodWorker.java:146)
at org.testng.internal.TestMethodWorker.run(TestMethodWorker.java:128)
at java.base/java.util.ArrayList.forEach(ArrayList.java:1511)
at org.testng.TestRunner.privateRun(TestRunner.java:794)
at org.testng.TestRunner.run(TestRunner.java:596)
at org.testng.SuiteRunner.runTest(SuiteRunner.java:377)
at org.testng.SuiteRunner.runSequentially(SuiteRunner.java:371)
at org.testng.SuiteRunner.privateRun(SuiteRunner.java:332)
at org.testng.SuiteRunner.run(SuiteRunner.java:276)
at org.testng.SuiteRunnerWorker.runSuite(SuiteRunnerWorker.java:53)
at org.testng.SuiteRunnerWorker.run(SuiteRunnerWorker.java:96)
at org.testng.TestNG.runSuitesSequentially(TestNG.java:1212)
at org.testng.TestNG.runSuitesLocally(TestNG.java:1134)
at org.testng.TestNG.runSuites(TestNG.java:1063)
at org.testng.TestNG.run(TestNG.java:1031)
at org.testng.remote.AbstractRemoteTestNG.run(AbstractRemoteTestNG.java:115)
at org.testng.remote.RemoteTestNG.initAndRun(RemoteTestNG.java:251)
at org.testng.remote.RemoteTestNG.main(RemoteTestNG.java:77)
]]>
            </full-stacktrace>
          </exception> <!-- java.lang.Throwable -->
          <reporter-output>
          </reporter-output>
        </test-method> <!-- test4 -->
        <test-method is-config="true" signature="afterclass()[pri:0, instance:basic.Annotations2@29647f75]" started-at="2022-09-27T16:10:43 IST" name="afterclass" finished-at="2022-09-27T16:10:43 IST" duration-ms="3" status="PASS">
          <reporter-output>
          </reporter-output>
        </test-method> <!-- afterclass -->
      </class> <!-- basic.Annotations2 -->
    </test> <!-- Default test -->
  </suite> <!-- Default suite -->
</testng-results>
